Workbook
Name Slicer_Department_Name: #N/A
Name Slicer_Employment_Status: #N/A
Name Slicer_Performance_Band: #N/A
Name Slicer_Years__Hire_Date: #N/A

Sheet Raw_Employee_Data
A1: Emp ID | B1: First_Name | C1: Last_Name | D1: Dept Code | E1: Hire Date | F1: Salary | G1: Perf_Score | H1: Employment Status
A2: EMP127 | B2: Emily | C2: Brown | D2: IT02 | E2: 43093 | F2: 50361 | G2: 52 | H2: active
A3: EMP046 | B3: Richard | C3: Hernandez | D3: MKT04 | E3: 44659 | F3: 112673 | H3: ACTIVE
A4: EMP134 | B4: Emily | C4: Gonzalez | D4: IT02 | E4: 42431 | F4: $114,425 | G4: 54 | H4: LEFT
A5: EMP139 | B5: John | C5: Martinez | D5: FIN03 | E5: 45110 | F5: 103831 | G5: 70 | H5: active
A6: EMP112 | B6: Thomas | C6: Smith | D6: IT02 | E6: 44977 | F6: 73785 | G6: 40 | H6: Left
A7: EMP030 | B7: Emily | C7: Johnson | D7: OPS06 | E7: 02-Mar-20 | F7: 115882 | G7: 49 | H7: ACTIVE
A8: EMP096 | B8: John | C8: Wilson | D8: OPS06 | E8: 45272 | F8: 59980 | G8: 70 | H8: Left
A9: EMP098 | B9: Jessica | C9: Smith | D9: OPS06 | E9: 44174 | F9: 68728 | G9: 45 | H9: ACTIVE
A10: EMP095 | C10: Rodriguez | D10: FIN03 | E10: 43107 | F10: 102139 | G10: 79 | H10: active
A11: EMP140 | B11: Michael | C11: Martinez | D11: SAL05 | E11: 42676 | F11: 94998 | G11: 58 | H11: Active
A12: EMP020 | B12: Emily | C12: Miller | D12: sal05 | E12: 43911 | F12: $118,635 | G12: 49 | H12: Active
A13: EMP057 | B13: Emily | C13: Hernandez | D13: IT02 | E13: 42425 | F13: 76918 | G13: 62 | H13: Actv
A14: EMP016 | B14: Jane | C14: Williams | D14: mkt04 | E14: 17-Jun-21 | F14: 61408 | G14: 48 | H14: ACTIVE
A15: EMP070 | B15: Jane | C15: Miller | D15: MKT04 | E15: 44001 | F15: 99990 | G15: 54 | H15: Actv
A16: EMP025 | B16: Robert | C16: Jones | D16: MKT04 | E16: 43820 | F16: 80385 | H16: active
A17: EMP031 | B17: Thomas | C17: Rodriguez | D17: SAL05 | E17: 45169 | F17: 65290 | G17: 77 | H17: active
A18: EMP126 | B18: Emily | C18: Davis | D18: IT02 | E18: 42337 | F18: 105765 | G18: 42 | H18: Active
A19: EMP109 | B19: James | C19: Martinez | D19: SAL05 | E19: 42899 | F19: 102921 | G19: 49 | H19: ACTIVE
A20: EMP057 | B20: Emily | C20: Hernandez | D20: IT02 | E20: 42425 | F20: 76918 | G20: 62 | H20: Actv
A21: EMP066 | B21: Ashley | C21: Lopez | D21: MKT04 | E21: 43235 | F21: 73984 | G21: 93 | H21: Actv
A22: EMP120 | B22: Amanda | C22: Gonzalez | D22: IT02 | E22: 42575 | G22: 75 | H22: Actv
A23: EMP019 | B23: Michael | C23: Hernandez | D23: FIN03 | E23: 43076 | F23: 118527 | G23: 50 | H23: Actv
A24: EMP013 | B24: Richard | C24: Hernandez | D24: MKT04 | E24: 44353 | F24: 107871 | G24: 88 | H24: active
A25: EMP010 | B25: Michael | C25: Rodriguez | D25: IT02 | E25: 44815 | F25: 93956 | G25: 50 | H25: LEFT
A26: EMP032 | B26: Jessica | C26: Johnson | D26: FIN03 | E26: 42565 | F26: 100851 | G26: 64 | H26: ACTIVE
A27: EMP082 | B27: Ashley | C27: Williams | D27: SAL05 | E27: 44728 | F27: 68655 | G27: 32 | H27: active
A28: EMP052 | C28: Williams | D28: SAL05 | E28: 45134 | F28: 81205 | G28: 59 | H28: Actv
A29: EMP129 | B29: John | C29: Wilson | D29: SAL05 | E29: 09/24/2019 | F29: $77,610 | G29: 88 | H29: Actv
A30: EMP146 | B30: Thomas | C30: Rodriguez | D30: it02 | E30: 44765 | F30: $50,873 | G30: 90 | H30: Active
A31: EMP099 | B31: Michael | C31: Wilson | D31: fin03 | E31: 13-May-18 | F31: 85312 | G31: 66 | H31: active
A32: EMP015 | B32: John | C32: Rodriguez | D32: SAL05 | E32: 42202 | G32: 68 | H32: active
A33: EMP076 | B33: Thomas | C33: Hernandez | D33: OPS06 | E33: 05-Aug-15 | F33: 97055 | G33: 80 | H33: Actv
A34: EMP137 | B34: Michael | C34: Johnson | D34: IT02 | E34: 45195 | F34: 66069 | G34: 72 | H34: Actv
A35: EMP056 | B35: Sarah | C35: Brown | D35: it02 | E35: 10-Jun-19 | F35: 90157 | G35: 58 | H35: active
A36: EMP125 | B36: Jane | C36: Martinez | D36: HR01 | E36: 44578 | F36: 59899 | G36: 78 | H36: Actv
A37: EMP085 | B37: Emily | C37: Jones | D37: FIN03 | E37: 03-Jul-17 | F37: 113389 | G37: 30 | H37: ACTIVE
A38: EMP106 | C38: Brown | D38: IT02 | E38: 01-Sep-15 | F38: 102691 | G38: 52 | H38: Active
A39: EMP043 | B39: John | C39: Wilson | D39: OPS06 | E39: 03-Aug-22 | F39: 111845 | G39: 98 | H39: active
A40: EMP068 | B40: Melissa | C40: Brown | D40: SAL05 | E40: 06/29/2022 | F40: 69219 | G40: 93 | H40: Actv
...

Sheet Transformed_Raw_Employee_Data
A1: Emp ID | B1: First_Name | C1: Last_Name | D1: Full Name | E1: Dept Code | F1: Department Name | G1: Hire Date | H1: Year of Service | I1: Salary | J1: Perf_Score | K1: Employment Status | L1: Performance Band | M1: Projected Bonus | N1: Bonus Amount
A2: EMP127 | B2: Emily | C2: Brown | D2: =_xlfn.TEXTJOIN(" ",TRUE,B2,C2) -> Emily Brown | E2: IT02 | F2: =_xlfn.XLOOKUP(E2,Lookup_Departments!$A$2:$A$7,Lookup_Departments!$B$2:$B$7) -> Information Technology | G2: 43093 | H2: 8 | I2: 50361 | J2: 52 | K2: Active | L2: {=_xlfn.IFS(J2<=49,"Needs Improvement",J2<=69,"Developing",J2<=84,"Achieving",J2<=94,"Exceeding",J2<=100,"Outstanding")} -> Developing | M2: =_xlfn.XLOOKUP(Transformed_Raw_Employee_Data!L2,Lookup_Performance!$C$2:$C$6,Lookup_Performance!$D$2:$D$6) -> 0.02 | N2: =I2*M2 -> 1007.22
A3: EMP046 | B3: Richard | C3: Hernandez | D3: =_xlfn.TEXTJOIN(" ",TRUE,B3,C3) -> Richard Hernandez | E3: MKT04 | F3: =_xlfn.XLOOKUP(E3,Lookup_Departments!$A$2:$A$7,Lookup_Departments!$B$2:$B$7) -> Marketing | G3: 44777 | H3: 3 | I3: 112673 | J3: 62.473684 | K3: Active | L3: {=_xlfn.IFS(J3<=49,"Needs Improvement",J3<=69,"Developing",J3<=84,"Achieving",J3<=94,"Exceeding",J3<=100,"Outstanding")} -> Developing | M3: =_xlfn.XLOOKUP(Transformed_Raw_Employee_Data!L3,Lookup_Performance!$C$2:$C$6,Lookup_Performance!$D$2:$D$6) -> 0.02 | N3: =I3*M3 -> 2253.46
A4: EMP134 | B4: Emily | C4: Gonzalez | D4: =_xlfn.TEXTJOIN(" ",TRUE,B4,C4) -> Emily Gonzalez | E4: IT02 | F4: =_xlfn.XLOOKUP(E4,Lookup_Departments!$A$2:$A$7,Lookup_Departments!$B$2:$B$7) -> Information Technology | G4: 42403 | H4: 10 | I4: 114425 | J4: 54 | K4: Left | L4: {=_xlfn.IFS(J4<=49,"Needs Improvement",J4<=69,"Developing",J4<=84,"Achieving",J4<=94,"Exceeding",J4<=100,"Outstanding")} -> Developing | M4: =_xlfn.XLOOKUP(Transformed_Raw_Employee_Data!L4,Lookup_Performance!$C$2:$C$6,Lookup_Performance!$D$2:$D$6) -> 0.02 | N4: =I4*M4 -> 2288.5
A5: EMP139 | B5: John | C5: Martinez | D5: =_xlfn.TEXTJOIN(" ",TRUE,B5,C5) -> John Martinez | E5: FIN03 | F5: =_xlfn.XLOOKUP(E5,Lookup_Departments!$A$2:$A$7,Lookup_Departments!$B$2:$B$7) -> Finance | G5: 44992 | H5: 3 | I5: 103831 | J5: 70 | K5: Active | L5: {=_xlfn.IFS(J5<=49,"Needs Improvement",J5<=69,"Developing",J5<=84,"Achieving",J5<=94,"Exceeding",J5<=100,"Outstanding")} -> Achieving | M5: =_xlfn.XLOOKUP(Transformed_Raw_Employee_Data!L5,Lookup_Performance!$C$2:$C$6,Lookup_Performance!$D$2:$D$6) -> 0.05 | N5: =I5*M5 -> 5191.55
A6: EMP112 | B6: Thomas | C6: Smith | D6: =_xlfn.TEXTJOIN(" ",TRUE,B6,C6) -> Thomas Smith | E6: IT02 | F6: =_xlfn.XLOOKUP(E6,Lookup_Departments!$A$2:$A$7,Lookup_Departments!$B$2:$B$7) -> Information Technology | G6: 44977 | H6: 3 | I6: 73785 | J6: 40 | K6: Left | L6: {=_xlfn.IFS(J6<=49,"Needs Improvement",J6<=69,"Developing",J6<=84,"Achieving",J6<=94,"Exceeding",J6<=100,"Outstanding")} -> Needs Improvement | M6: =_xlfn.XLOOKUP(Transformed_Raw_Employee_Data!L6,Lookup_Performance!$C$2:$C$6,Lookup_Performance!$D$2:$D$6) -> 0 | N6: =I6*M6 -> 0 | R6: Helper Table 1
A7: EMP030 | B7: Emily | C7: Johnson | D7: =_xlfn.TEXTJOIN(" ",TRUE,B7,C7) -> Emily Johnson | E7: OPS06 | F7: =_xlfn.XLOOKUP(E7,Lookup_Departments!$A$2:$A$7,Lookup_Departments!$B$2:$B$7) -> Operations | G7: 43864 | H7: 6 | I7: 115882 | J7: 49 | K7: Active | L7: {=_xlfn.IFS(J7<=49,"Needs Improvement",J7<=69,"Developing",J7<=84,"Achieving",J7<=94,"Exceeding",J7<=100,"Outstanding")} -> Needs Improvement | M7: =_xlfn.XLOOKUP(Transformed_Raw_Employee_Data!L7,Lookup_Performance!$C$2:$C$6,Lookup_Performance!$D$2:$D$6) -> 0 | N7: =I7*M7 -> 0 | P7: SUMIF | Q7: COUNTIF | R7: MEAN | S7: Department | T7: Column1
A8: EMP096 | B8: John | C8: Wilson | D8: =_xlfn.TEXTJOIN(" ",TRUE,B8,C8) -> John Wilson | E8: OPS06 | F8: =_xlfn.XLOOKUP(E8,Lookup_Departments!$A$2:$A$7,Lookup_Departments!$B$2:$B$7) -> Operations | G8: 45272 | H8: 2 | I8: 59980 | J8: 70 | K8: Left | L8: {=_xlfn.IFS(J8<=49,"Needs Improvement",J8<=69,"Developing",J8<=84,"Achieving",J8<=94,"Exceeding",J8<=100,"Outstanding")} -> Achieving | M8: =_xlfn.XLOOKUP(Transformed_Raw_Employee_Data!L8,Lookup_Performance!$C$2:$C$6,Lookup_Performance!$D$2:$D$6) -> 0.05 | N8: =I8*M8 -> 2999 | P8: =SUMIF(E2:E151,E2,I2:I151) -> 2824947.8 | Q8: =COUNTIF(E2:E151,E2) -> 36 | R8: =P8/Q8 -> 78470.773 | S8: IT | T8: 68901.167
A9: EMP098 | B9: Jessica | C9: Smith | D9: =_xlfn.TEXTJOIN(" ",TRUE,B9,C9) -> Jessica Smith | E9: OPS06 | F9: =_xlfn.XLOOKUP(E9,Lookup_Departments!$A$2:$A$7,Lookup_Departments!$B$2:$B$7) -> Operations | G9: 44086 | H9: 5 | I9: 68728 | J9: 45 | K9: Active | L9: {=_xlfn.IFS(J9<=49,"Needs Improvement",J9<=69,"Developing",J9<=84,"Achieving",J9<=94,"Exceeding",J9<=100,"Outstanding")} -> Needs Improvement | M9: =_xlfn.XLOOKUP(Transformed_Raw_Employee_Data!L9,Lookup_Performance!$C$2:$C$6,Lookup_Performance!$D$2:$D$6) -> 0 | N9: =I9*M9 -> 0 | P9: =SUMIF(E2:E151,E3,I2:I151) -> 1620154.7 | Q9: =COUNTIF(E2:E151,E3) -> 19 | R9: =P9/Q9 -> 85271.302 | S9: Marketing | T9: 81007.737
A10: EMP095 | C10: Rodriguez | D10: =_xlfn.TEXTJOIN(" ",TRUE,B10,C10) -> Rodriguez | E10: FIN03 | F10: =_xlfn.XLOOKUP(E10,Lookup_Departments!$A$2:$A$7,Lookup_Departments!$B$2:$B$7) -> Finance | G10: 43282 | H10: 8 | I10: 102139 | J10: 79 | K10: Active | L10: {=_xlfn.IFS(J10<=49,"Needs Improvement",J10<=69,"Developing",J10<=84,"Achieving",J10<=94,"Exceeding",J10<=100,"Outstanding")} -> Achieving | M10: =_xlfn.XLOOKUP(Transformed_Raw_Employee_Data!L10,Lookup_Performance!$C$2:$C$6,Lookup_Performance!$D$2:$D$6) -> 0.05 | N10: =I10*M10 -> 5106.95 | P10: =SUMIF(E2:E151,E5,I2:I151) -> 1448398.8 | Q10: =COUNTIF(E2:E151,E5) -> 17 | R10: =P10/Q10 -> 85199.931 | S10: Finance | T10: 72419.941
A11: EMP140 | B11: Michael | C11: Martinez | D11: =_xlfn.TEXTJOIN(" ",TRUE,B11,C11) -> Michael Martinez | E11: SAL05 | F11: =_xlfn.XLOOKUP(E11,Lookup_Departments!$A$2:$A$7,Lookup_Departments!$B$2:$B$7) -> Sales | G11: 42411 | H11: 10 | I11: 94998 | J11: 58 | K11: Active | L11: {=_xlfn.IFS(J11<=49,"Needs Improvement",J11<=69,"Developing",J11<=84,"Achieving",J11<=94,"Exceeding",J11<=100,"Outstanding")} -> Developing | M11: =_xlfn.XLOOKUP(Transformed_Raw_Employee_Data!L11,Lookup_Performance!$C$2:$C$6,Lookup_Performance!$D$2:$D$6) -> 0.02 | N11: =I11*M11 -> 1899.96 | P11: =SUMIF(E2:E151,E7,I2:I151) -> 2302808.3 | Q11: =COUNTIF(E2:E151,E7) -> 29 | R11: =P11/Q11 -> 79407.182 | S11: Operations | T11: 74284.138
A12: EMP020 | B12: Emily | C12: Miller | D12: =_xlfn.TEXTJOIN(" ",TRUE,B12,C12) -> Emily Miller | E12: SAL05 | F12: =_xlfn.XLOOKUP(E12,Lookup_Departments!$A$2:$A$7,Lookup_Departments!$B$2:$B$7) -> Sales | G12: 43911 | H12: 6 | I12: 118635 | J12: 49 | K12: Active | L12: {=_xlfn.IFS(J12<=49,"Needs Improvement",J12<=69,"Developing",J12<=84,"Achieving",J12<=94,"Exceeding",J12<=100,"Outstanding")} -> Needs Improvement | M12: =_xlfn.XLOOKUP(Transformed_Raw_Employee_Data!L12,Lookup_Performance!$C$2:$C$6,Lookup_Performance!$D$2:$D$6) -> 0 | N12: =I12*M12 -> 0 | P12: =SUMIF(E2:E151,E11,I2:I151) -> 2525557 | Q12: =COUNTIF(E2:E151,E11) -> 31 | R12: =P12/Q12 -> 81469.58 | S12: Sales | T12: 64757.871
A13: EMP057 | B13: Emily | C13: Hernandez | D13: =_xlfn.TEXTJOIN(" ",TRUE,B13,C13) -> Emily Hernandez | E13: IT02 | F13: =_xlfn.XLOOKUP(E13,Lookup_Departments!$A$2:$A$7,Lookup_Departments!$B$2:$B$7) -> Information Technology | G13: 42425 | H13: 10 | I13: 76918 | J13: 62 | K13: Active | L13: {=_xlfn.IFS(J13<=49,"Needs Improvement",J13<=69,"Developing",J13<=84,"Achieving",J13<=94,"Exceeding",J13<=100,"Outstanding")} -> Developing | M13: =_xlfn.XLOOKUP(Transformed_Raw_Employee_Data!L13,Lookup_Performance!$C$2:$C$6,Lookup_Performance!$D$2:$D$6) -> 0.02 | N13: =I13*M13 -> 1538.36 | P13: =SUMIF(E2:E151,E35,I2:I151) -> 1536940.6 | Q13: =COUNTIF(E2:E151,E35) -> 18 | R13: =P13/Q13 -> 85385.59 | S13: Human Resources | T13: 80891.611
A14: EMP016 | B14: Jane | C14: Williams | D14: =_xlfn.TEXTJOIN(" ",TRUE,B14,C14) -> Jane Williams | E14: MKT04 | F14: =_xlfn.XLOOKUP(E14,Lookup_Departments!$A$2:$A$7,Lookup_Departments!$B$2:$B$7) -> Marketing | G14: 44364 | H14: 5 | I14: 61408 | J14: 48 | K14: Active | L14: {=_xlfn.IFS(J14<=49,"Needs Improvement",J14<=69,"Developing",J14<=84,"Achieving",J14<=94,"Exceeding",J14<=100,"Outstanding")} -> Needs Improvement | M14: =_xlfn.XLOOKUP(Transformed_Raw_Employee_Data!L14,Lookup_Performance!$C$2:$C$6,Lookup_Performance!$D$2:$D$6) -> 0 | N14: =I14*M14 -> 0
A15: EMP070 | B15: Jane | C15: Miller | D15: =_xlfn.TEXTJOIN(" ",TRUE,B15,C15) -> Jane Miller | E15: MKT04 | F15: =_xlfn.XLOOKUP(E15,Lookup_Departments!$A$2:$A$7,Lookup_Departments!$B$2:$B$7) -> Marketing | G15: 44001 | H15: 6 | I15: 99990 | J15: 54 | K15: Active | L15: {=_xlfn.IFS(J15<=49,"Needs Improvement",J15<=69,"Developing",J15<=84,"Achieving",J15<=94,"Exceeding",J15<=100,"Outstanding")} -> Developing | M15: =_xlfn.XLOOKUP(Transformed_Raw_Employee_Data!L15,Lookup_Performance!$C$2:$C$6,Lookup_Performance!$D$2:$D$6) -> 0.02 | N15: =I15*M15 -> 1999.8 | R15: Helper Table 2
A16: EMP025 | B16: Robert | C16: Jones | D16: =_xlfn.TEXTJOIN(" ",TRUE,B16,C16) -> Robert Jones | E16: MKT04 | F16: =_xlfn.XLOOKUP(E16,Lookup_Departments!$A$2:$A$7,Lookup_Departments!$B$2:$B$7) -> Marketing | G16: 43820 | H16: 6 | I16: 80385 | J16: 62.473684 | K16: Active | L16: {=_xlfn.IFS(J16<=49,"Needs Improvement",J16<=69,"Developing",J16<=84,"Achieving",J16<=94,"Exceeding",J16<=100,"Outstanding")} -> Developing | M16: =_xlfn.XLOOKUP(Transformed_Raw_Employee_Data!L16,Lookup_Performance!$C$2:$C$6,Lookup_Performance!$D$2:$D$6) -> 0.02 | N16: =I16*M16 -> 1607.7 | P16: SUMIF | Q16: COUNTIF | R16: MEAN | S16: Department
A17: EMP031 | B17: Thomas | C17: Rodriguez | D17: =_xlfn.TEXTJOIN(" ",TRUE,B17,C17) -> Thomas Rodriguez | E17: SAL05 | F17: =_xlfn.XLOOKUP(E17,Lookup_Departments!$A$2:$A$7,Lookup_Departments!$B$2:$B$7) -> Sales | G17: 45169 | H17: 2 | I17: 65290 | J17: 77 | K17: Active | L17: {=_xlfn.IFS(J17<=49,"Needs Improvement",J17<=69,"Developing",J17<=84,"Achieving",J17<=94,"Exceeding",J17<=100,"Outstanding")} -> Achieving | M17: =_xlfn.XLOOKUP(Transformed_Raw_Employee_Data!L17,Lookup_Performance!$C$2:$C$6,Lookup_Performance!$D$2:$D$6) -> 0.05 | N17: =I17*M17 -> 3264.5 | P17: =SUMIF(E2:E151,E2,J2:J151) -> 2349.5 | Q17: =COUNTIF(E2:E151,E2) -> 36 | R17: =P17/Q17 -> 65.263889 | S17: IT
A18: EMP126 | B18: Emily | C18: Davis | D18: =_xlfn.TEXTJOIN(" ",TRUE,B18,C18) -> Emily Davis | E18: IT02 | F18: =_xlfn.XLOOKUP(E18,Lookup_Departments!$A$2:$A$7,Lookup_Departments!$B$2:$B$7) -> Information Technology | G18: 42337 | H18: 10 | I18: 105765 | J18: 42 | K18: Active | L18: {=_xlfn.IFS(J18<=49,"Needs Improvement",J18<=69,"Developing",J18<=84,"Achieving",J18<=94,"Exceeding",J18<=100,"Outstanding")} -> Needs Improvement | M18: =_xlfn.XLOOKUP(Transformed_Raw_Employee_Data!L18,Lookup_Performance!$C$2:$C$6,Lookup_Performance!$D$2:$D$6) -> 0 | N18: =I18*M18 -> 0 | P18: =SUMIF(E2:E151,E3,J2:J151) -> 1374.4211 | Q18: =COUNTIF(E2:E151,E3) -> 19 | R18: =P18/Q18 -> 72.33795 | S18: Marketing
A19: EMP109 | B19: James | C19: Martinez | D19: =_xlfn.TEXTJOIN(" ",TRUE,B19,C19) -> James Martinez | E19: SAL05 | F19: =_xlfn.XLOOKUP(E19,Lookup_Departments!$A$2:$A$7,Lookup_Departments!$B$2:$B$7) -> Sales | G19: 42899 | H19: 9 | I19: 102921 | J19: 49 | K19: Active | L19: {=_xlfn.IFS(J19<=49,"Needs Improvement",J19<=69,"Developing",J19<=84,"Achieving",J19<=94,"Exceeding",J19<=100,"Outstanding")} -> Needs Improvement | M19: =_xlfn.XLOOKUP(Transformed_Raw_Employee_Data!L19,Lookup_Performance!$C$2:$C$6,Lookup_Performance!$D$2:$D$6) -> 0 | N19: =I19*M19 -> 0 | P19: =SUMIF(E2:E151,E5,J2:J151) -> 1172 | Q19: =COUNTIF(E2:E151,E5) -> 17 | R19: =P19/Q19 -> 68.941176 | S19: Finance
A20: EMP066 | B20: Ashley | C20: Lopez | D20: =_xlfn.TEXTJOIN(" ",TRUE,B20,C20) -> Ashley Lopez | E20: MKT04 | F20: =_xlfn.XLOOKUP(E20,Lookup_Departments!$A$2:$A$7,Lookup_Departments!$B$2:$B$7) -> Marketing | G20: 43235 | H20: 8 | I20: 73984 | J20: 93 | K20: Active | L20: {=_xlfn.IFS(J20<=49,"Needs Improvement",J20<=69,"Developing",J20<=84,"Achieving",J20<=94,"Exceeding",J20<=100,"Outstanding")} -> Exceeding | M20: =_xlfn.XLOOKUP(Transformed_Raw_Employee_Data!L20,Lookup_Performance!$C$2:$C$6,Lookup_Performance!$D$2:$D$6) -> 0.08 | N20: =I20*M20 -> 5918.72 | P20: =SUMIF(E2:E151,E7,J2:J151) -> 2013 | Q20: =COUNTIF(E2:E151,E7) -> 29 | R20: =P20/Q20 -> 69.413793 | S20: Operations
A21: EMP120 | B21: Amanda | C21: Gonzalez | D21: =_xlfn.TEXTJOIN(" ",TRUE,B21,C21) -> Amanda Gonzalez | E21: IT02 | F21: =_xlfn.XLOOKUP(E21,Lookup_Departments!$A$2:$A$7,Lookup_Departments!$B$2:$B$7) -> Information Technology | G21: 42575 | H21: 9 | I21: 68901.167 | J21: 75 | K21: Active | L21: {=_xlfn.IFS(J21<=49,"Needs Improvement",J21<=69,"Developing",J21<=84,"Achieving",J21<=94,"Exceeding",J21<=100,"Outstanding")} -> Achieving | M21: =_xlfn.XLOOKUP(Transformed_Raw_Employee_Data!L21,Lookup_Performance!$C$2:$C$6,Lookup_Performance!$D$2:$D$6) -> 0.05 | N21: =I21*M21 -> 3445.0583 | P21: =SUMIF(E2:E151,E11,J2:J151) -> 1982 | Q21: =COUNTIF(E2:E151,E11) -> 31 | R21: =P21/Q21 -> 63.935484 | S21: Sales
A22: EMP019 | B22: Michael | C22: Hernandez | D22: =_xlfn.TEXTJOIN(" ",TRUE,B22,C22) -> Michael Hernandez | E22: FIN03 | F22: =_xlfn.XLOOKUP(E22,Lookup_Departments!$A$2:$A$7,Lookup_Departments!$B$2:$B$7) -> Finance | G22: 42928 | H22: 8 | I22: 118527 | J22: 50 | K22: Active | L22: {=_xlfn.IFS(J22<=49,"Needs Improvement",J22<=69,"Developing",J22<=84,"Achieving",J22<=94,"Exceeding",J22<=100,"Outstanding")} -> Developing | M22: =_xlfn.XLOOKUP(Transformed_Raw_Employee_Data!L22,Lookup_Performance!$C$2:$C$6,Lookup_Performance!$D$2:$D$6) -> 0.02 | N22: =I22*M22 -> 2370.54 | P22: =SUMIF(E2:E151,E35,J2:J151) -> 1278 | Q22: =COUNTIF(E2:E151,E35) -> 18 | R22: =P22/Q22 -> 71 | S22: Human Resources
A23: EMP013 | B23: Richard | C23: Hernandez | D23: =_xlfn.TEXTJOIN(" ",TRUE,B23,C23) -> Richard Hernandez | E23: MKT04 | F23: =_xlfn.XLOOKUP(E23,Lookup_Departments!$A$2:$A$7,Lookup_Departments!$B$2:$B$7) -> Marketing | G23: 44353 | H23: 5 | I23: 107871 | J23: 88 | K23: Active | L23: {=_xlfn.IFS(J23<=49,"Needs Improvement",J23<=69,"Developing",J23<=84,"Achieving",J23<=94,"Exceeding",J23<=100,"Outstanding")} -> Exceeding | M23: =_xlfn.XLOOKUP(Transformed_Raw_Employee_Data!L23,Lookup_Performance!$C$2:$C$6,Lookup_Performance!$D$2:$D$6) -> 0.08 | N23: =I23*M23 -> 8629.68
A24: EMP010 | B24: Michael | C24: Rodriguez | D24: =_xlfn.TEXTJOIN(" ",TRUE,B24,C24) -> Michael Rodriguez | E24: IT02 | F24: =_xlfn.XLOOKUP(E24,Lookup_Departments!$A$2:$A$7,Lookup_Departments!$B$2:$B$7) -> Information Technology | G24: 44874 | H24: 3 | I24: 93956 | J24: 50 | K24: Left | L24: {=_xlfn.IFS(J24<=49,"Needs Improvement",J24<=69,"Developing",J24<=84,"Achieving",J24<=94,"Exceeding",J24<=100,"Outstanding")} -> Developing | M24: =_xlfn.XLOOKUP(Transformed_Raw_Employee_Data!L24,Lookup_Performance!$C$2:$C$6,Lookup_Performance!$D$2:$D$6) -> 0.02 | N24: =I24*M24 -> 1879.12
A25: EMP032 | B25: Jessica | C25: Johnson | D25: =_xlfn.TEXTJOIN(" ",TRUE,B25,C25) -> Jessica Johnson | E25: FIN03 | F25: =_xlfn.XLOOKUP(E25,Lookup_Departments!$A$2:$A$7,Lookup_Departments!$B$2:$B$7) -> Finance | G25: 42565 | H25: 9 | I25: 100851 | J25: 64 | K25: Active | L25: {=_xlfn.IFS(J25<=49,"Needs Improvement",J25<=69,"Developing",J25<=84,"Achieving",J25<=94,"Exceeding",J25<=100,"Outstanding")} -> Developing | M25: =_xlfn.XLOOKUP(Transformed_Raw_Employee_Data!L25,Lookup_Performance!$C$2:$C$6,Lookup_Performance!$D$2:$D$6) -> 0.02 | N25: =I25*M25 -> 2017.02
A26: EMP082 | B26: Ashley | C26: Williams | D26: =_xlfn.TEXTJOIN(" ",TRUE,B26,C26) -> Ashley Williams | E26: SAL05 | F26: =_xlfn.XLOOKUP(E26,Lookup_Departments!$A$2:$A$7,Lookup_Departments!$B$2:$B$7) -> Sales | G26: 44728 | H26: 4 | I26: 68655 | J26: 32 | K26: Active | L26: {=_xlfn.IFS(J26<=49,"Needs Improvement",J26<=69,"Developing",J26<=84,"Achieving",J26<=94,"Exceeding",J26<=100,"Outstanding")} -> Needs Improvement | M26: =_xlfn.XLOOKUP(Transformed_Raw_Employee_Data!L26,Lookup_Performance!$C$2:$C$6,Lookup_Performance!$D$2:$D$6) -> 0 | N26: =I26*M26 -> 0
A27: EMP052 | C27: Williams | D27: =_xlfn.TEXTJOIN(" ",TRUE,B27,C27) -> Williams | E27: SAL05 | F27: =_xlfn.XLOOKUP(E27,Lookup_Departments!$A$2:$A$7,Lookup_Departments!$B$2:$B$7) -> Sales | G27: 45134 | H27: 2 | I27: 81205 | J27: 59 | K27: Active | L27: {=_xlfn.IFS(J27<=49,"Needs Improvement",J27<=69,"Developing",J27<=84,"Achieving",J27<=94,"Exceeding",J27<=100,"Outstanding")} -> Developing | M27: =_xlfn.XLOOKUP(Transformed_Raw_Employee_Data!L27,Lookup_Performance!$C$2:$C$6,Lookup_Performance!$D$2:$D$6) -> 0.02 | N27: =I27*M27 -> 1624.1
A28: EMP129 | B28: John | C28: Wilson | D28: =_xlfn.TEXTJOIN(" ",TRUE,B28,C28) -> John Wilson | E28: SAL05 | F28: =_xlfn.XLOOKUP(E28,Lookup_Departments!$A$2:$A$7,Lookup_Departments!$B$2:$B$7) -> Sales | G28: 43732 | H28: 6 | I28: 77610 | J28: 88 | K28: Active | L28: {=_xlfn.IFS(J28<=49,"Needs Improvement",J28<=69,"Developing",J28<=84,"Achieving",J28<=94,"Exceeding",J28<=100,"Outstanding")} -> Exceeding | M28: =_xlfn.XLOOKUP(Transformed_Raw_Employee_Data!L28,Lookup_Performance!$C$2:$C$6,Lookup_Performance!$D$2:$D$6) -> 0.08 | N28: =I28*M28 -> 6208.8
A29: EMP146 | B29: Thomas | C29: Rodriguez | D29: =_xlfn.TEXTJOIN(" ",TRUE,B29,C29) -> Thomas Rodriguez | E29: IT02 | F29: =_xlfn.XLOOKUP(E29,Lookup_Departments!$A$2:$A$7,Lookup_Departments!$B$2:$B$7) -> Information Technology | G29: 44765 | H29: 3 | I29: 50873 | J29: 90 | K29: Active | L29: {=_xlfn.IFS(J29<=49,"Needs Improvement",J29<=69,"Developing",J29<=84,"Achieving",J29<=94,"Exceeding",J29<=100,"Outstanding")} -> Exceeding | M29: =_xlfn.XLOOKUP(Transformed_Raw_Employee_Data!L29,Lookup_Performance!$C$2:$C$6,Lookup_Performance!$D$2:$D$6) -> 0.08 | N29: =I29*M29 -> 4069.84
A30: EMP099 | B30: Michael | C30: Wilson | D30: =_xlfn.TEXTJOIN(" ",TRUE,B30,C30) -> Michael Wilson | E30: FIN03 | F30: =_xlfn.XLOOKUP(E30,Lookup_Departments!$A$2:$A$7,Lookup_Departments!$B$2:$B$7) -> Finance | G30: 43233 | H30: 8 | I30: 85312 | J30: 66 | K30: Active | L30: {=_xlfn.IFS(J30<=49,"Needs Improvement",J30<=69,"Developing",J30<=84,"Achieving",J30<=94,"Exceeding",J30<=100,"Outstanding")} -> Developing | M30: =_xlfn.XLOOKUP(Transformed_Raw_Employee_Data!L30,Lookup_Performance!$C$2:$C$6,Lookup_Performance!$D$2:$D$6) -> 0.02 | N30: =I30*M30 -> 1706.24
A31: EMP015 | B31: John | C31: Rodriguez | D31: =_xlfn.TEXTJOIN(" ",TRUE,B31,C31) -> John Rodriguez | E31: SAL05 | F31: =_xlfn.XLOOKUP(E31,Lookup_Departments!$A$2:$A$7,Lookup_Departments!$B$2:$B$7) -> Sales | G31: 42202 | H31: 10 | I31: 64757.871 | J31: 68 | K31: Active | L31: {=_xlfn.IFS(J31<=49,"Needs Improvement",J31<=69,"Developing",J31<=84,"Achieving",J31<=94,"Exceeding",J31<=100,"Outstanding")} -> Developing | M31: =_xlfn.XLOOKUP(Transformed_Raw_Employee_Data!L31,Lookup_Performance!$C$2:$C$6,Lookup_Performance!$D$2:$D$6) -> 0.02 | N31: =I31*M31 -> 1295.1574
A32: EMP076 | B32: Thomas | C32: Hernandez | D32: =_xlfn.TEXTJOIN(" ",TRUE,B32,C32) -> Thomas Hernandez | E32: OPS06 | F32: =_xlfn.XLOOKUP(E32,Lookup_Departments!$A$2:$A$7,Lookup_Departments!$B$2:$B$7) -> Operations | G32: 42132 | H32: 11 | I32: 97055 | J32: 80 | K32: Active | L32: {=_xlfn.IFS(J32<=49,"Needs Improvement",J32<=69,"Developing",J32<=84,"Achieving",J32<=94,"Exceeding",J32<=100,"Outstanding")} -> Achieving | M32: =_xlfn.XLOOKUP(Transformed_Raw_Employee_Data!L32,Lookup_Performance!$C$2:$C$6,Lookup_Performance!$D$2:$D$6) -> 0.05 | N32: =I32*M32 -> 4852.75
A33: EMP137 | B33: Michael | C33: Johnson | D33: =_xlfn.TEXTJOIN(" ",TRUE,B33,C33) -> Michael Johnson | E33: IT02 | F33: =_xlfn.XLOOKUP(E33,Lookup_Departments!$A$2:$A$7,Lookup_Departments!$B$2:$B$7) -> Information Technology | G33: 45195 | H33: 2 | I33: 66069 | J33: 72 | K33: Active | L33: {=_xlfn.IFS(J33<=49,"Needs Improvement",J33<=69,"Developing",J33<=84,"Achieving",J33<=94,"Exceeding",J33<=100,"Outstanding")} -> Achieving | M33: =_xlfn.XLOOKUP(Transformed_Raw_Employee_Data!L33,Lookup_Performance!$C$2:$C$6,Lookup_Performance!$D$2:$D$6) -> 0.05 | N33: =I33*M33 -> 3303.45
A34: EMP056 | B34: Sarah | C34: Brown | D34: =_xlfn.TEXTJOIN(" ",TRUE,B34,C34) -> Sarah Brown | E34: IT02 | F34: =_xlfn.XLOOKUP(E34,Lookup_Departments!$A$2:$A$7,Lookup_Departments!$B$2:$B$7) -> Information Technology | G34: 43744 | H34: 6 | I34: 90157 | J34: 58 | K34: Active | L34: {=_xlfn.IFS(J34<=49,"Needs Improvement",J34<=69,"Developing",J34<=84,"Achieving",J34<=94,"Exceeding",J34<=100,"Outstanding")} -> Developing | M34: =_xlfn.XLOOKUP(Transformed_Raw_Employee_Data!L34,Lookup_Performance!$C$2:$C$6,Lookup_Performance!$D$2:$D$6) -> 0.02 | N34: =I34*M34 -> 1803.14
A35: EMP125 | B35: Jane | C35: Martinez | D35: =_xlfn.TEXTJOIN(" ",TRUE,B35,C35) -> Jane Martinez | E35: HR01 | F35: =_xlfn.XLOOKUP(E35,Lookup_Departments!$A$2:$A$7,Lookup_Departments!$B$2:$B$7) -> Human Resources | G35: 44578 | H35: 4 | I35: 59899 | J35: 78 | K35: Active | L35: {=_xlfn.IFS(J35<=49,"Needs Improvement",J35<=69,"Developing",J35<=84,"Achieving",J35<=94,"Exceeding",J35<=100,"Outstanding")} -> Achieving | M35: =_xlfn.XLOOKUP(Transformed_Raw_Employee_Data!L35,Lookup_Performance!$C$2:$C$6,Lookup_Performance!$D$2:$D$6) -> 0.05 | N35: =I35*M35 -> 2994.95
A36: EMP085 | B36: Emily | C36: Jones | D36: =_xlfn.TEXTJOIN(" ",TRUE,B36,C36) -> Emily Jones | E36: FIN03 | F36: =_xlfn.XLOOKUP(E36,Lookup_Departments!$A$2:$A$7,Lookup_Departments!$B$2:$B$7) -> Finance | G36: 42801 | H36: 9 | I36: 113389 | J36: 30 | K36: Active | L36: {=_xlfn.IFS(J36<=49,"Needs Improvement",J36<=69,"Developing",J36<=84,"Achieving",J36<=94,"Exceeding",J36<=100,"Outstanding")} -> Needs Improvement | M36: =_xlfn.XLOOKUP(Transformed_Raw_Employee_Data!L36,Lookup_Performance!$C$2:$C$6,Lookup_Performance!$D$2:$D$6) -> 0 | N36: =I36*M36 -> 0
A37: EMP106 | C37: Brown | D37: =_xlfn.TEXTJOIN(" ",TRUE,B37,C37) -> Brown | E37: IT02 | F37: =_xlfn.XLOOKUP(E37,Lookup_Departments!$A$2:$A$7,Lookup_Departments!$B$2:$B$7) -> Information Technology | G37: 42013 | H37: 11 | I37: 102691 | J37: 52 | K37: Active | L37: {=_xlfn.IFS(J37<=49,"Needs Improvement",J37<=69,"Developing",J37<=84,"Achieving",J37<=94,"Exceeding",J37<=100,"Outstanding")} -> Developing | M37: =_xlfn.XLOOKUP(Transformed_Raw_Employee_Data!L37,Lookup_Performance!$C$2:$C$6,Lookup_Performance!$D$2:$D$6) -> 0.02 | N37: =I37*M37 -> 2053.82
A38: EMP043 | B38: John | C38: Wilson | D38: =_xlfn.TEXTJOIN(" ",TRUE,B38,C38) -> John Wilson | E38: OPS06 | F38: =_xlfn.XLOOKUP(E38,Lookup_Departments!$A$2:$A$7,Lookup_Departments!$B$2:$B$7) -> Operations | G38: 44628 | H38: 4 | I38: 111845 | J38: 98 | K38: Active | L38: {=_xlfn.IFS(J38<=49,"Needs Improvement",J38<=69,"Developing",J38<=84,"Achieving",J38<=94,"Exceeding",J38<=100,"Outstanding")} -> Outstanding | M38: =_xlfn.XLOOKUP(Transformed_Raw_Employee_Data!L38,Lookup_Performance!$C$2:$C$6,Lookup_Performance!$D$2:$D$6) -> 0.12 | N38: =I38*M38 -> 13421.4
A39: EMP068 | B39: Melissa | C39: Brown | D39: =_xlfn.TEXTJOIN(" ",TRUE,B39,C39) -> Melissa Brown | E39: SAL05 | F39: =_xlfn.XLOOKUP(E39,Lookup_Departments!$A$2:$A$7,Lookup_Departments!$B$2:$B$7) -> Sales | G39: 44741 | H39: 4 | I39: 69219 | J39: 93 | K39: Active | L39: {=_xlfn.IFS(J39<=49,"Needs Improvement",J39<=69,"Developing",J39<=84,"Achieving",J39<=94,"Exceeding",J39<=100,"Outstanding")} -> Exceeding | M39: =_xlfn.XLOOKUP(Transformed_Raw_Employee_Data!L39,Lookup_Performance!$C$2:$C$6,Lookup_Performance!$D$2:$D$6) -> 0.08 | N39: =I39*M39 -> 5537.52
A40: EMP128 | B40: Michael | C40: Smith | D40: =_xlfn.TEXTJOIN(" ",TRUE,B40,C40) -> Michael Smith | E40: FIN03 | F40: =_xlfn.XLOOKUP(E40,Lookup_Departments!$A$2:$A$7,Lookup_Departments!$B$2:$B$7) -> Finance | G40: 43949 | H40: 6 | I40: 72419.941 | J40: 80 | K40: Left | L40: {=_xlfn.IFS(J40<=49,"Needs Improvement",J40<=69,"Developing",J40<=84,"Achieving",J40<=94,"Exceeding",J40<=100,"Outstanding")} -> Achieving | M40: =_xlfn.XLOOKUP(Transformed_Raw_Employee_Data!L40,Lookup_Performance!$C$2:$C$6,Lookup_Performance!$D$2:$D$6) -> 0.05 | N40: =I40*M40 -> 3620.9971
...

Sheet Lookup_Departments
A1: Dept_Code | B1: Department_Name
A2: HR01 | B2: Human Resources
A3: IT02 | B3: Information Technology
A4: FIN03 | B4: Finance
A5: MKT04 | B5: Marketing
A6: SAL05 | B6: Sales
A7: OPS06 | B7: Operations

Sheet Lookup_Performance
A1: Min_Score | B1: Max_Score | C1: Performance_Band | D1: Bonus_Percentage
A2: 0 | B2: 49 | C2: Needs Improvement | D2: 0
A3: 50 | B3: 69 | C3: Developing | D3: 0.02
A4: 70 | B4: 84 | C4: Achieving | D4: 0.05
A5: 85 | B5: 94 | C5: Exceeding | D5: 0.08
A6: 95 | B6: 100 | C6: Outstanding | D6: 0.12

Sheet Analysis
A2: Total Employee | D2: Average Salary Per Department | I2: Attrition Rate by Departments
A3: Total Employee | D3: Departments | E3: Average Salary | I3: Departments | J3: Attrition Rate
A4: 150 | D4: Finance | E4: 85199.931 | I4: Information Technology | J4: 0.24
D5: Human Resources | E5: 85385.59 | I5: Active | J5: 0.77777778
D6: Information Technology | E6: 78470.773 | G6: =GETPIVOTDATA("Salary",$D$3) -> 81725.382 | I6: Left | J6: 0.16666667
B7: =GETPIVOTDATA("Emp ID",$A$3) -> 150 | D7: Marketing | E7: 85271.302 | I7: Resigned | J7: 0.055555556
D8: Operations | E8: 79407.182 | I8: Sales | J8: 0.20666667
D9: Sales | E9: 81469.58 | I9: Active | J9: 0.80645161
D10: Grand Total | E10: 81725.382 | I10: Left | J10: 0.12903226
I11: Resigned | J11: 0.064516129
I12: Operations | J12: 0.19333333
I13: Active | J13: 0.62068966
A14: Performance By Status | E14: Bonus Payout by Performance Band | I14: Left | J14: 0.20689655
A15: Employment Status | B15: Average Performance Score | E15: Performance Band | F15: Bonus Payout | I15: Resigned | J15: 0.17241379
A16: Resigned | B16: 76.4 | E16: Achieving | F16: 161572 | I16: Marketing | J16: 0.12666667
A17: Active | B17: 67.417423 | E17: Exceeding | F17: 142974.05 | I17: Active | J17: 0.84210526
A18: Left | B18: 66.020833 | E18: Outstanding | F18: 90647.18 | I18: Left | J18: 0.15789474
A19: Grand Total | B19: 67.792807 | E19: Developing | F19: 82050.114 | I19: Human Resources | J19: 0.12
E20: Needs Improvement | F20: 0 | I20: Active | J20: 0.83333333
E21: Grand Total | F21: 477243.34 | G21: =GETPIVOTDATA("Bonus Amount",$E$15) -> 477243.34 | I21: Left | J21: 0.11111111
B22: =GETPIVOTDATA("Perf_Score",$A$15) -> 67.792807 | I22: Resigned | J22: 0.055555556
I23: Finance | J23: 0.11333333
B24: Employee Hiring Trend by Year | I24: Active | J24: 0.82352941
A25: Performance Band | B25: Count of Emp ID | E25: Average Performance Score by Department | I25: Left | J25: 0.17647059
A26: 2015 | B26: 13 | E26: Performance Band | F26: Average of Perf_Score | I26: Grand Total | J26: 1
A27: 2016 | B27: 17 | E27: Marketing | F27: 72.33795
A28: 2017 | B28: 19 | E28: Human Resources | F28: 71
A29: 2018 | B29: 18 | E29: Operations | F29: 69.413793
A30: 2019 | B30: 16 | E30: Finance | F30: 68.941176
A31: 2020 | B31: 17 | E31: Information Technology | F31: 65.263889
A32: 2021 | B32: 15 | E32: Sales | F32: 63.935484
A33: 2022 | B33: 18 | E33: Grand Total | F33: 67.792807
A34: 2023 | B34: 17
A35: Grand Total | B35: 150
D39: Average Performance Score by Hire Year
D40: Hire Year | E40: Average Perf_Score
D41: 2015 | E41: 70.230769
D42: 2016 | E42: 64.470588
D43: 2017 | E43: 65.368421
D44: 2018 | E44: 65.777778
...

Sheet Dashboard
